{
  "cveId": "CVE-2024-9979",
  "title": "Pyo3: risk of use-after-free in `borrowed` reads from python weak references",
  "description": "A flaw was found in PyO3. This vulnerability causes a use-after-free issue, potentially leading to memory corruption or crashes via unsound borrowing from weak Python references.",
  "publishedDate": "2024-10-15T14:01:54.309000+00:00",
  "lastModifiedDate": "2025-01-09T17:27:23.921000+00:00",
  "severity": "MEDIUM",
  "cvssMetrics": [
    {
      "version": "3.1",
      "vectorString": "CVSS:3.1/AV:L/AC:L/PR:L/UI:N/S:U/C:L/I:L/A:L",
      "baseScore": 5.3,
      "baseSeverity": "MEDIUM"
    }
  ],
  "epss": {
    "score": 0.0008,
    "percentile": 24.606
  },
  "riskScore": 35,
  "exploitationStatus": "UNKNOWN",
  "affectedSystems": {
    "cpeMatches": [],
    "vendors": ["red hat"],
    "products": [
      "red hat enterprise linux 9",
      "red hat enterprise linux 8",
      "red hat ansible automation platform 2"
    ]
  },
  "references": [
    {
      "url": "https://access.redhat.com/security/cve/CVE-2024-9979",
      "source": "",
      "tags": ["vdb-entry", "x_refsource_REDHAT"]
    },
    {
      "url": "https://bugzilla.redhat.com/show_bug.cgi?id=2318646",
      "source": "RHBZ#2318646",
      "tags": ["issue-tracking", "x_refsource_REDHAT"]
    },
    {
      "url": "https://crates.io/crates/pyo3",
      "source": "",
      "tags": []
    },
    {
      "url": "https://github.com/PyO3/pyo3/pull/4590",
      "source": "",
      "tags": []
    },
    {
      "url": "https://rustsec.org/advisories/RUSTSEC-2024-0378.html",
      "source": "",
      "tags": []
    }
  ],
  "attackTechniques": [],
  "metadata": {
    "tags": ["CWE-416"],
    "requiresUserInteraction": null,
    "requiresPrivileges": null,
    "attackVector": null,
    "sources": [
      {
        "name": "CVEList",
        "url": "https://github.com/CVEProject/cvelistV5/blob/main/cves/2024/9xxx/CVE-2024-9979.json",
        "lastModified": "2025-01-09T17:27:23.921000+00:00"
      }
    ]
  }
}
